[34m[1mwandb[39m[22m: [33mWARNING[39m Calling wandb.run.save without any arguments is deprecated.Changes to attributes are automatically persisted.
INFO: Initializing distributed: GLOBAL_RANK: 1, MEMBER: 2/4
INFO:lightning.fabric.utilities.distributed:Initializing distributed: GLOBAL_RANK: 1, MEMBER: 2/4
INFO:timm.models._builder:Loading pretrained weights from Hugging Face hub (timm/eva_large_patch14_336.in22k_ft_in22k_in1k)
INFO:timm.models._hub:[timm/eva_large_patch14_336.in22k_ft_in22k_in1k] Safe alternative available for 'pytorch_model.bin' (as 'model.safetensors'). Loading weights using safetensors.
INFO:RS_utils:{'input_size': (3, 336, 336), 'interpolation': 'bicubic', 'mean': (0.48145466, 0.4578275, 0.40821073), 'std': (0.26862954, 0.26130258, 0.27577711), 'crop_pct': 1.0, 'crop_mode': 'squash'}
INFO:RS_utils:Compose(
    Resize(size=(336, 336), interpolation=bicubic, max_size=None, antialias=warn)
    CenterCrop(size=(336, 336))
    ToTensor()
    Normalize(mean=tensor([0.4815, 0.4578, 0.4082]), std=tensor([0.2686, 0.2613, 0.2758]))
)
fabric
Traceback (most recent call last):
  File "/mnt/hdd/eric/.tmp_ipy/15.Lab_Detection/07.Challenge/01.MapYourCity_HuggingFace/011.finetune.py", line 121, in <module>
    for iteration, (X, y) in enumerate(trainloader):
  File "/mnt/hdd/eric/.conda/envs/mapv2/lib/python3.8/site-packages/lightning/fabric/wrappers.py", line 331, in __iter__
    for item in self._dataloader:
  File "/mnt/hdd/eric/.conda/envs/mapv2/lib/python3.8/site-packages/torch/utils/data/dataloader.py", line 630, in __next__
    data = self._next_data()
  File "/mnt/hdd/eric/.conda/envs/mapv2/lib/python3.8/site-packages/torch/utils/data/dataloader.py", line 1345, in _next_data
    return self._process_data(data)
  File "/mnt/hdd/eric/.conda/envs/mapv2/lib/python3.8/site-packages/torch/utils/data/dataloader.py", line 1371, in _process_data
    data.reraise()
  File "/mnt/hdd/eric/.conda/envs/mapv2/lib/python3.8/site-packages/torch/_utils.py", line 694, in reraise
    raise exception
TypeError: Caught TypeError in DataLoader worker process 0.
Original Traceback (most recent call last):
  File "/mnt/hdd/eric/.conda/envs/mapv2/lib/python3.8/site-packages/torch/utils/data/_utils/worker.py", line 308, in _worker_loop
    data = fetcher.fetch(index)
  File "/mnt/hdd/eric/.conda/envs/mapv2/lib/python3.8/site-packages/torch/utils/data/_utils/fetch.py", line 51, in fetch
    data = [self.dataset[idx] for idx in possibly_batched_index]
  File "/mnt/hdd/eric/.conda/envs/mapv2/lib/python3.8/site-packages/torch/utils/data/_utils/fetch.py", line 51, in <listcomp>
    data = [self.dataset[idx] for idx in possibly_batched_index]
  File "/mnt/hdd/eric/.tmp_ipy/15.Lab_Detection/07.Challenge/01.MapYourCity_HuggingFace/map_dataset.py", line 116, in __getitem__
    X1 = self.resize(X1)
  File "/mnt/hdd/eric/.tmp_ipy/15.Lab_Detection/07.Challenge/01.MapYourCity_HuggingFace/map_dataset.py", line 80, in resize
    img_ = resize_transform(img_)
  File "/mnt/hdd/eric/.conda/envs/mapv2/lib/python3.8/site-packages/torch/nn/modules/module.py", line 1518, in _wrapped_call_impl
    return self._call_impl(*args, **kwargs)
  File "/mnt/hdd/eric/.conda/envs/mapv2/lib/python3.8/site-packages/torch/nn/modules/module.py", line 1527, in _call_impl
    return forward_call(*args, **kwargs)
  File "/mnt/hdd/eric/.conda/envs/mapv2/lib/python3.8/site-packages/torchvision/transforms/transforms.py", line 361, in forward
    return F.resize(img, self.size, self.interpolation, self.max_size, self.antialias)
  File "/mnt/hdd/eric/.conda/envs/mapv2/lib/python3.8/site-packages/torchvision/transforms/functional.py", line 479, in resize
    output_size = _compute_resized_output_size((image_height, image_width), size, max_size)
  File "/mnt/hdd/eric/.conda/envs/mapv2/lib/python3.8/site-packages/torchvision/transforms/functional.py", line 377, in _compute_resized_output_size
    if max_size <= requested_new_short:
TypeError: '<=' not supported between instances of 'tuple' and 'int'